<?xml version="1.0" ?>
<!-- =================================================================================== -->
<!-- |    This document was autogenerated by xacro from robot.urdf.xacro               | -->
<!-- |    EDITING THIS FILE BY HAND IS NOT RECOMMENDED                                 | -->
<!-- =================================================================================== -->
<robot name="robot">
  <!-- Specify some standard inertial calculations https://en.wikipedia.org/wiki/List_of_moments_of_inertia -->
  <!-- These make use of xacro's mathematical functionality -->
  <material name="white">
    <color rgba="1 1 1 1"/>
  </material>
  <material name="orange">
    <color rgba="1 0.3 0.1 1"/>
  </material>
  <material name="blue">
    <color rgba="0.2 0.2 1 1"/>
  </material>
  <material name="black">
    <color rgba="0 0 0 1"/>
  </material>
  <!-- BASE -->
  <link name="base_link">
    <visual>
      <origin xyz="-0.6052 -0.31115 0"/>
      <geometry>
        <mesh filename="package://arm_urdf/meshes/base.stl" scale="0.001 0.001 0.001 "/>
      </geometry>
      <material name="white"/>
    </visual>
    <collision>
      <origin xyz="-0.6052 -0.31115 0"/>
      <geometry>
        <mesh filename="package://arm_urdf/meshes/base.stl" scale="0.001 0.001 0.001 "/>
      </geometry>
    </collision>
    <inertial>
      <origin rpy="0 0 0" xyz="-0.3 0 0.25"/>
      <mass value="40"/>
      <inertia ixx="2.033333333333333" ixy="0.0" ixz="0.0" iyy="2.033333333333333" iyz="0.0" izz="2.4"/>
    </inertial>
  </link>
  <gazebo reference="base_link">
    <material>Gazebo/White</material>
  </gazebo>
  <!-- SETS THE HEIGHT OF THE ARM -->
  <joint name="base_joint" type="fixed">
    <parent link="base_link"/>
    <child link="shoulder_base"/>
    <origin xyz="0 0 1.175"/>
  </joint>
  <!-- SHOULDER -->
  <link name="shoulder_base">
    <visual>
      <origin xyz="-0.0425 -0.09775 -0.05"/>
      <geometry>
        <mesh filename="package://arm_urdf/meshes/shoulder_base.stl" scale="0.001 0.001 0.001 "/>
      </geometry>
      <material name="black"/>
    </visual>
    <collision>
      <origin xyz="-0.0425 -0.09775 -0.05"/>
      <geometry>
        <mesh filename="package://arm_urdf/meshes/shoulder_base.stl" scale="0.001 0.001 0.001 "/>
      </geometry>
    </collision>
    <inertial>
      <origin rpy="0 0 0" xyz="0 0 0.1"/>
      <mass value="1"/>
      <inertia ixx="0.00041666666666666675" ixy="0.0" ixz="0.0" iyy="0.00041666666666666675" iyz="0.0" izz="0.00041666666666666675"/>
    </inertial>
  </link>
  <gazebo reference="shoulder_base">
    <material>Gazebo/Black</material>
  </gazebo>
  <joint name="shoulder_joint" type="revolute">
    <origin rpy="1.5707963267948966 0 0" xyz="0 0 0"/>
    <parent link="shoulder_base"/>
    <child link="shoulder_link"/>
    <axis xyz="0 0 1"/>
    <limit effort="100" lower="-1.5707963267948966" upper="0.4" velocity="100"/>
  </joint>
  <link name="shoulder_link">
    <visual>
      <origin rpy="0 1.5707963267948966 0" xyz="-0.05 -0.075 0.075"/>
      <geometry>
        <mesh filename="package://arm_urdf/meshes/shoulder.stl" scale="0.001 0.001 0.001 "/>
      </geometry>
      <material name="blue"/>
    </visual>
    <collision>
      <origin rpy="0 1.5707963267948966 0" xyz="-0.05 -0.075 0.075"/>
      <geometry>
        <mesh filename="package://arm_urdf/meshes/shoulder.stl" scale="0.001 0.001 0.001 "/>
      </geometry>
    </collision>
    <inertial>
      <origin rpy="0 0 0" xyz="0.08 0 0"/>
      <mass value="1"/>
      <inertia ixx="0.0027083333333333334" ixy="0.0" ixz="0.0" iyy="0.0019270833333333332" iyz="0.0" izz="0.0008854166666666668"/>
    </inertial>
  </link>
  <gazebo reference="shoulder_link">
    <material>Gazebo/Blue</material>
  </gazebo>
  <joint name="bicept_joint" type="revolute">
    <parent link="shoulder_link"/>
    <child link="bicept_link"/>
    <origin rpy="0 1.5707963267948966 0" xyz="0.05 0 0"/>
    <axis xyz="0 0 1"/>
    <limit effort="100" lower="-1.5707963267948966" upper="1.5707963267948966" velocity="100"/>
  </joint>
  <link name="bicept_link">
    <visual>
      <origin rpy="0 1.5707963267948966 1.5707963267948966" xyz="0.050 -0.060 0.383"/>
      <geometry>
        <mesh filename="package://arm_urdf/meshes/bicept.stl" scale="0.001 0.001 0.001 "/>
      </geometry>
      <material name="orange"/>
    </visual>
    <collision>
      <origin rpy="0 1.5707963267948966 1.5707963267948966" xyz="0.050 -0.060 0.383"/>
      <geometry>
        <mesh filename="package://arm_urdf/meshes/bicept.stl" scale="0.001 0.001 0.001 "/>
      </geometry>
    </collision>
    <inertial>
      <origin rpy="0 0 0" xyz="0 0 0.195"/>
      <mass value="2.2"/>
      <inertia ixx="0.02260023333333334" ixy="0.0" ixz="0.0" iyy="0.02260023333333334" iyz="0.0" izz="0.0020625"/>
    </inertial>
  </link>
  <gazebo reference="bicept_link">
    <material>Gazebo/Orange</material>
  </gazebo>
  <joint name="elbow_joint" type="revolute">
    <parent link="bicept_link"/>
    <child link="elbow_link"/>
    <origin rpy="0 -1.5707963267948966 0" xyz="0 0 0.343"/>
    <axis xyz="0 0 1"/>
    <limit effort="100" lower="0" upper="2" velocity="100"/>
  </joint>
  <link name="elbow_link">
    <visual>
      <origin rpy="0 0 1.5707963267948966" xyz="0.049 -0.04 -0.0286"/>
      <geometry>
        <mesh filename="package://arm_urdf/meshes/elbow.stl" scale="0.001 0.001 0.001 "/>
      </geometry>
      <material name="blue"/>
    </visual>
    <collision>
      <origin rpy="0 0 1.5707963267948966" xyz="0.049 -0.04 -0.0286"/>
      <geometry>
        <mesh filename="package://arm_urdf/meshes/elbow.stl" scale="0.001 0.001 0.001 "/>
      </geometry>
    </collision>
    <inertial>
      <origin rpy="0 0 0" xyz="0.03 0 0"/>
      <mass value="0.5"/>
      <inertia ixx="0.00040833333333333336" ixy="0.0" ixz="0.0" iyy="0.00024166666666666667" iyz="0.0" izz="0.00024166666666666667"/>
    </inertial>
  </link>
  <gazebo reference="elbow_link">
    <material>Gazebo/Blue</material>
  </gazebo>
  <joint name="forearm_joint" type="revolute">
    <parent link="elbow_link"/>
    <child link="forearm_link"/>
    <origin rpy="0 1.5707963267948966 0" xyz="0.038 0 0"/>
    <axis xyz="0 0 1"/>
    <limit effort="100" lower="-1.5707963267948966" upper="1.5707963267948966" velocity="100"/>
  </joint>
  <link name="forearm_link">
    <visual>
      <origin rpy="0 1.5707963267948966 1.5707963267948966" xyz="0.042 -0.04 0.289"/>
      <geometry>
        <mesh filename="package://arm_urdf/meshes/forearm.stl" scale="0.001 0.001 0.001 "/>
      </geometry>
      <material name="orange"/>
    </visual>
    <collision>
      <origin rpy="0 1.5707963267948966 1.5707963267948966" xyz="0.042 -0.04 0.289"/>
      <geometry>
        <mesh filename="package://arm_urdf/meshes/forearm.stl" scale="0.001 0.001 0.001 "/>
      </geometry>
    </collision>
    <inertial>
      <origin rpy="0 0 0" xyz="0 0 0.13"/>
      <mass value="1.5"/>
      <inertia ixx="0.0066625" ixy="0.0" ixz="0.0" iyy="0.0066625" iyz="0.0" izz="0.0012250000000000002"/>
    </inertial>
  </link>
  <gazebo reference="forearm_link">
    <material>Gazebo/Orange</material>
  </gazebo>
  <joint name="wrist_joint1" type="revolute">
    <parent link="forearm_link"/>
    <child link="wrist_link1"/>
    <origin rpy="-1.5707963267948966 0 0" xyz="0 0 0.264"/>
    <axis xyz="1 0 0"/>
    <limit effort="100" lower="-0.3" upper="1" velocity="100"/>
  </joint>
  <link name="wrist_link1">
    <visual>
      <origin rpy="0 -1.5707963267948966 -1.5707963267948966 " xyz="-0.05 -0.025 -0.02502"/>
      <geometry>
        <mesh filename="package://arm_urdf/meshes/wrist_1.stl" scale="0.001 0.001 0.001 "/>
      </geometry>
      <material name="blue"/>
    </visual>
    <collision>
      <origin rpy="0 -1.5707963267948966 -1.5707963267948966 " xyz="-0.05 -0.025 -0.02502"/>
      <geometry>
        <mesh filename="package://arm_urdf/meshes/wrist_1.stl" scale="0.001 0.001 0.001 "/>
      </geometry>
    </collision>
    <inertial>
      <origin rpy="0 0 0" xyz="0 0 0.038"/>
      <mass value="0.5"/>
      <inertia ixx="0.00010833333333333334" ixy="0.0" ixz="0.0" iyy="0.0004208333333333334" iyz="0.0" izz="0.0005208333333333334"/>
    </inertial>
  </link>
  <gazebo reference="wrist_link1">
    <material>Gazebo/Blue</material>
  </gazebo>
  <joint name="wrist_joint2" type="revolute">
    <parent link="wrist_link1"/>
    <child link="wrist_link2"/>
    <origin rpy="0 -1.5707963267948966 0" xyz="0 0 0"/>
    <axis xyz="1 0 0"/>
    <limit effort="100" lower="-0.7853981633974483" upper="0.7853981633974483" velocity="100"/>
  </joint>
  <link name="wrist_link2">
    <visual>
      <origin rpy="-1.5707963267948966 -3.141592653589793 0" xyz="0.0435 -0.0235 -0.0235"/>
      <geometry>
        <mesh filename="package://arm_urdf/meshes/wrist_2.stl" scale="0.001 0.001 0.001 "/>
      </geometry>
      <material name="orange"/>
    </visual>
    <collision>
      <origin rpy="-1.5707963267948966 -3.141592653589793 0" xyz="0.0435 -0.0235 -0.0235"/>
      <geometry>
        <mesh filename="package://arm_urdf/meshes/wrist_2.stl" scale="0.001 0.001 0.001 "/>
      </geometry>
    </collision>
    <inertial>
      <origin rpy="0 0 0" xyz="0.02 0 0"/>
      <mass value="0.2"/>
      <inertia ixx="1.3333333333333333e-05" ixy="0.0" ixz="0.0" iyy="4.833333333333335e-05" iyz="0.0" izz="4.833333333333335e-05"/>
    </inertial>
  </link>
  <gazebo reference="wrist_link2">
    <material>Gazebo/Orange</material>
  </gazebo>
  <joint name="tip_joint" type="fixed">
    <parent link="wrist_link2"/>
    <child link="tip"/>
    <origin xyz="0 -0.9 0"/>
  </joint>
  <link name="tip">
    <!-- SQUARE TIP -->
    <visual>
      <origin xyz="0 0 0"/>
      <geometry>
        <box size="0.025 0.025 0.025"/>
      </geometry>
      <material name="white"/>
    </visual>
    <collision>
      <origin xyz="0 0 0"/>
      <geometry>
        <box size="0.025 0.025 0.025"/>
      </geometry>
    </collision>
    <!-- BLADE -->
    <visual>
      <origin xyz="0 0.45 0"/>
      <geometry>
        <box size="0.01 0.9 0.01"/>
      </geometry>
      <material name="white"/>
    </visual>
    <collision>
      <origin xyz="0 0.45 0"/>
      <geometry>
        <box size="0.01 0.9 0.01"/>
      </geometry>
    </collision>
    <inertial>
      <origin rpy="0 0 0" xyz="0 0.45 0"/>
      <mass value="0.5"/>
      <inertia ixx="0.03375416666666667" ixy="0.0" ixz="0.0" iyy="8.333333333333334e-06" iyz="0.0" izz="0.03375416666666667"/>
    </inertial>
  </link>
  <gazebo reference="tip">
    <material>Gazebo/Orange</material>
    <mu1 value="0.001"/>
    <mu2 value="0.001"/>
  </gazebo>
  <gazebo>
    <gazebo reference="base_link">
      <material>Gazebo/White</material>
    </gazebo>
    <gazebo reference="shoulder_base">
      <material>Gazebo/Black</material>
    </gazebo>
    <gazebo reference="shoulder_link">
      <material>Gazebo/Orange</material>
    </gazebo>
    <gazebo reference="elbow_link">
      <material>Gazebo/Blue</material>
    </gazebo>
    <gazebo reference="forearm_link">
      <material>Gazebo/Orange</material>
    </gazebo>
    <gazebo reference="wrist_link1">
      <material>Gazebo/Blue</material>
    </gazebo>
    <gazebo reference="wrist_link2">
      <material>Gazebo/Orange</material>
    </gazebo>
    <gazebo reference="tip">
      <material>Gazebo/White</material>
    </gazebo>
  </gazebo>
</robot>
