<?xml version="1.0"?>
<robot xmlns:xacro="http://www.ros.org/wiki/xacro" >

    <material name="white">
        <color rgba="1 1 1 1"/>
    </material>

    <material name="orange">
        <color rgba="1 0.3 0.1 1"/>
    </material>

    <material name="blue">
        <color rgba="0.2 0.2 1 1"/>
    </material>

    <material name="black">
        <color rgba="0 0 0 1"/>
    </material>



    <!-- BASE -->
    <link name="base_link">

    </link>

    <joint name="base_joint" type="fixed">
        <parent link ="base_link"/>
        <child link="shoulder_link"/>
        <origin xyz="0 0 1"/>
    </joint>

    <!-- SHOULDER -->
    <link name = "shoulder_link">
        <visual>
            <origin xyz="0 0 -0.05"/>
            <geometry>
                <box size="0.1 0.1 0.1"/>
            </geometry>
            <material name="blue"/>
        </visual>
    </link>



    <joint name="shoulder_joint" type="revolute">
        <parent link ="shoulder_link"/>
        <child link="bicept_link"/>
        <origin xyz="0 0 -0.1" rpy="0 0 0"/>
        <axis xyz="0 1 0" rpy="0 0 0"/>
        <limit lower="0" upper="${pi/2}" velocity ="100" effort = "100"/>
    </joint>



    <link name = "bicept_link">
        <visual>
            <origin xyz="0 0 0.5"/>
            <geometry>
                <box size="0.01 0.01 0.1"/>
            </geometry>
            <material name="orange"/>
        </visual>
    </link>

    <joint name="bicept_joint" type="revolute">
        <parent link ="bicept_link"/>
        <child link="elbow_link"/>
        <origin xyz="0 0 0.1" rpy="0 0 0"/>
        <axis xyz="0 1 0" rpy="0 0 0"/>
        <limit lower="0" upper="${pi/2}" velocity ="100" effort = "100"/>
    </joint>

    <link name = "elbow_link">
        <visual>
            <origin xyz="0 0 0.05"/>
            <geometry>
                <box size="0.1 0.11 0.1"/>
            </geometry>
            <material name="white"/>
        </visual>
    </link>
</robot>