<?xml version="1.0"?>
<robot xmlns:xacro="http://www.ros.org/wiki/xacro" >

    <xacro:include filename="inertial_macros.xacro"/>
    <material name="white">
        <color rgba="1 1 1 1"/>
    </material>

    <material name="orange">
        <color rgba="1 0.3 0.1 1"/>
    </material>

    <material name="blue">
        <color rgba="0.2 0.2 1 1"/>
    </material>

    <material name="black">
        <color rgba="0 0 0 1"/>
    </material>



    <!-- BASE -->
    <link name="base_link">
        <visual>
            <origin xyz="-0.6052 -0.31115 0"/>
            <geometry>
                <mesh filename="package://arm_urdf/meshes/base.stl" scale="0.001 0.001 0.001 "/>
            </geometry>
            <material name="white"/>
        </visual>
        <collision>
            <origin xyz="0 0 0.5"/>
            <geometry>
                <box size="0.05 0.05 1"/>
            </geometry>
        </collision>
    </link>

    <!-- SETS THE HEIGHT OF THE ARM -->
    <joint name="base_joint" type="fixed">
        <parent link ="base_link"/>
        <child link="shoulder_base"/>
        <origin xyz="0 0 1.175"/>
    </joint>

    <!-- SHOULDER -->
    <link name = "shoulder_base">
        <visual>
            <origin xyz="-0.0425 -0.09775 -0.05"/>
            <geometry>
                <mesh filename="package://arm_urdf/meshes/shoulder_base.stl" scale="0.001 0.001 0.001 "/>
            </geometry>
            <material name="black"/>
        </visual>
    </link>


   <joint name="shoulder_joint" type="revolute">
        <origin xyz="0 0 0" rpy="${pi/2} 0 0"/>    
        <parent link ="shoulder_base"/>
        <child link="shoulder_link"/>
        <axis xyz="0 0 1" />
        <limit lower="${-pi/2}" upper="0.4" velocity ="100" effort = "100"/>
    </joint>


    <link name = "shoulder_link">
        <visual>
            <origin xyz="-0.05 -0.075 0.075" rpy ="0 ${pi/2} 0"/>
            <geometry>
                <mesh filename="package://arm_urdf/meshes/shoulder.stl" scale="0.001 0.001 0.001 "/>
            </geometry>
            <material name="blue"/>
        </visual>
        <collision>
            <origin xyz="0.05 0 0"/>
            <geometry>
                <mesh filename="package://arm_urdf/meshes/shoulder.stl" scale="0.001 0.001 0.001 "/>
            </geometry>
        </collision>
        <xacro:inertial_box mass="0.5" x="0.1" y="0.05" z="0.05">
            <origin xyz="0.05 0 0" rpy= "0 0 0"/>
        </xacro:inertial_box >

    </link>

    <joint name="bicept_joint" type="revolute">
        <parent link ="shoulder_link"/>
        <child link="bicept_link"/>
        <origin xyz="0.05 0 0" rpy="0 ${pi/2} 0"/>
        <axis xyz="0 0 1" />
        <limit lower="${-pi/2}" upper="${pi/2}" velocity ="100" effort = "100"/>
    </joint>
 

    <link name = "bicept_link">
        <visual>
            <origin xyz="0.050 -0.060 0.383" rpy="0 ${pi/2} ${pi/2}"/>
            <geometry>
                <mesh filename="package://arm_urdf/meshes/bicept.stl" scale="0.001 0.001 0.001 "/>
            </geometry>
            <material name="orange"/>
        </visual>
        <collision>
            <origin xyz="0 0 0.1465"/>
            <geometry>
                <mesh filename="package://arm_urdf/meshes/bicept.stl" scale="0.001 0.001 0.001 "/>
            </geometry>
        </collision>
        <xacro:inertial_box mass = "3" x="0.05" y="0.05" z="0.293">
            <origin xyz="0 0 0.1465" rpy= "0 0 0"/>
        </xacro:inertial_box >
    </link>

    <joint name="elbow_joint" type="revolute">
        <parent link ="bicept_link"/>
        <child link="elbow_link"/>
        <origin xyz="0 0 0.343" rpy="0 ${-pi/2} 0"/>
        <axis xyz="0 0 1" />
        <limit lower="0" upper="2" velocity ="100" effort = "100"/>
    </joint>

    <link name = "elbow_link">
        <visual>
            <origin xyz="0.049 -0.04 -0.0286" rpy ="0 0 ${pi/2}"/>
            <geometry>
                <mesh filename="package://arm_urdf/meshes/elbow.stl" scale="0.001 0.001 0.001 "/>
            </geometry>
            <material name="blue"/>
        </visual>
        <collision>
            <origin xyz="0.05 0 0"/>
            <geometry>
                <mesh filename="package://arm_urdf/meshes/elbow.stl" scale="0.001 0.001 0.001 "/>
            </geometry>
        </collision>
        <xacro:inertial_box mass ="0.6" x="0.1" y="0.05" z="0.05">
            <origin xyz="0.05 0 0" rpy= "0 0 0"/>
        </xacro:inertial_box >
    </link>

    <joint name="forearm_joint" type="revolute">
        <parent link ="elbow_link"/>
        <child link="forearm_link"/>
        <origin xyz="0.038 0 0" rpy="0 ${pi/2} 0"/>
        <axis xyz="0 0 1" />
        <limit lower="${-pi/2}" upper="${pi/2}" velocity ="100" effort = "100"/>
    </joint>

    <link name = "forearm_link">
        <visual>
            <origin xyz="0.042 -0.04 0.289" rpy ="0 ${pi/2} ${pi/2}"/>
            <geometry>
                <mesh filename="package://arm_urdf/meshes/forearm.stl" scale="0.001 0.001 0.001 "/>
            </geometry>
            <material name="orange"/>
        </visual>
        <collision>
            <origin xyz="0 0 0.1"/>
            <geometry>
                <mesh filename="package://arm_urdf/meshes/forearm.stl" scale="0.001 0.001 0.001 "/>
            </geometry>
        </collision>
        <xacro:inertial_box mass ="2.5" x="0.05" y="0.05" z="0.2">
            <origin xyz="0 0 0.1" rpy= "0 0 0"/>
        </xacro:inertial_box >
    </link>

    <joint name="wrist_joint1" type="revolute">
        <parent link ="forearm_link"/>
        <child link="wrist_link1"/>
        <origin xyz="0 0 0.264" rpy="${-pi/2} 0 0"/>
        <axis xyz="1 0 0" />
        <limit lower="-0.3" upper="1" velocity ="100" effort = "100"/>
    </joint>

    <link name = "wrist_link1">
        <visual>
            <origin xyz="-0.05 -0.025 -0.02502" rpy="0 ${-pi/2} ${-pi/2} " />
            <geometry>
                <mesh filename="package://arm_urdf/meshes/wrist_1.stl" scale="0.001 0.001 0.001 "/>
            </geometry>
            <material name="blue"/>
        </visual>
    </link>

    <joint name="wrist_joint2" type="revolute">
        <parent link ="wrist_link1"/>
        <child link="wrist_link2"/>
        <origin xyz="0 0 0" rpy="0 ${-pi/2} 0"/>
        <axis xyz="1 0 0" />
        <limit lower="${-pi/4}" upper="${pi/4}" velocity ="100" effort = "100"/>
    </joint>

    <link name = "wrist_link2">
        <visual>     
            <origin xyz="0.0435 -0.0235 -0.0235" rpy="${-pi/2} ${-pi} 0"/>
            <geometry>
                <mesh filename="package://arm_urdf/meshes/wrist_2.stl" scale="0.001 0.001 0.001 "/>
            </geometry>
            <material name="orange"/>
        </visual>
        <collision>
            <origin xyz="0 -0.5 0"/>
            <geometry>
                <mesh filename="package://arm_urdf/meshes/wrist_2.stl" scale="0.001 0.001 0.001 "/>
            </geometry>
        </collision>
        <xacro:inertial_box mass ="0.5" x="0.2" y="1" z="0.2">
            <origin xyz="0 -0.5 0" rpy= "0 0 0"/>
        </xacro:inertial_box >
    </link>

    <joint name="tip_joint" type="fixed">
        <parent link ="wrist_link2"/>
        <child link="tip"/>
        <origin xyz="0 -0.9 0"/>
    </joint>

    <link name = "tip">
        <!-- SQUARE TIP -->
        <visual>
            <origin xyz="0 0 0"/>
            <geometry>
                <box size="0.025 0.025 0.025"/>
            </geometry>
            <material name="white"/>
        </visual>

        <!-- BLADE -->
        <visual>
            <origin xyz="0 0.45 0"/>
            <geometry>
                <box size="0.01 0.9 0.01" length="1"/>
            </geometry>
            <material name="white"/>
        </visual>
        <collision>
            <origin xyz="0 0 0"/>
            <geometry>
                <box size="0.05 0.05 0.05"/>
            </geometry>
        </collision>
    </link>

</robot>